Workbook

Sheet Cleaned_Appointment
A1: AppointmentID | B1: PatientID | C1: DoctorID | D1: Department | E1: Date | F1: Time | G1: Status | H1: Hour | I1: DayOfWeek
A2: N/A | B2: P96099 | C2: D26 | D2: Cardiology | E2: 45292 | F2: N/A | G2: N/A | H2: =IFERROR(HOUR(F2),"N/A") -> N/A | I2: =IFERROR(TEXT(E2,"dddd"),"N/A") -> Monday
A3: A7515 | B3: P16262 | C3: D1 | D3: Orthopedics | E3: 45545 | F3: 0.54166667 | G3: No Show | H3: =IFERROR(HOUR(F3),"N/A") -> 13 | I3: =IFERROR(TEXT(E3,"dddd"),"N/A") -> Tuesday
A4: A7537 | B4: P99601 | C4: D30 | D4: Cardiology | E4: 45643 | F4: 0.625 | G4: Completed | H4: =IFERROR(HOUR(F4),"N/A") -> 15 | I4: =IFERROR(TEXT(E4,"dddd"),"N/A") -> Tuesday
A5: A8866 | B5: P55235 | C5: D30 | D5: Neurology | E5: 45482 | F5: 0.64583333 | G5: Rescheduled | H5: =IFERROR(HOUR(F5),"N/A") -> 15 | I5: =IFERROR(TEXT(E5,"dddd"),"N/A") -> Tuesday
A6: A3039 | B6: P93372 | C6: D23 | D6: Pediatric | E6: 45516 | F6: 0.75 | G6: Cancelled | H6: =IFERROR(HOUR(F6),"N/A") -> 18 | I6: =IFERROR(TEXT(E6,"dddd"),"N/A") -> Monday
A7: A3237 | B7: P84444 | C7: D1 | D7: Pediatric | E7: 45357 | F7: 0.72916667 | G7: Rescheduled | H7: =IFERROR(HOUR(F7),"N/A") -> 17 | I7: =IFERROR(TEXT(E7,"dddd"),"N/A") -> Wednesday
A8: A8127 | B8: P41013 | C8: D24 | D8: Neurology | E8: 45383 | F8: 0.45833333 | G8: No Show | H8: =IFERROR(HOUR(F8),"N/A") -> 11 | I8: =IFERROR(TEXT(E8,"dddd"),"N/A") -> Monday
A9: A7025 | B9: P17235 | C9: D10 | D9: Neurology | E9: 45581 | F9: 0.625 | G9: No Show | H9: =IFERROR(HOUR(F9),"N/A") -> 15 | I9: =IFERROR(TEXT(E9,"dddd"),"N/A") -> Wednesday
A10: A8462 | B10: P35768 | C10: D8 | D10: Cardiology | E10: 45558 | F10: 0.64583333 | G10: Completed | H10: =IFERROR(HOUR(F10),"N/A") -> 15 | I10: =IFERROR(TEXT(E10,"dddd"),"N/A") -> Monday
A11: A9018 | B11: P28832 | C11: D14 | D11: Orthopedics | E11: 45395 | F11: 0.5625 | G11: Rescheduled | H11: =IFERROR(HOUR(F11),"N/A") -> 13 | I11: =IFERROR(TEXT(E11,"dddd"),"N/A") -> Saturday
A12: A7791 | B12: P29680 | C12: D28 | D12: Orthopedics | E12: 45460 | F12: 0.35416667 | G12: No Show | H12: =IFERROR(HOUR(F12),"N/A") -> 8 | I12: =IFERROR(TEXT(E12,"dddd"),"N/A") -> Monday
A13: A4362 | B13: P93978 | C13: D5 | D13: Orthopedics | E13: 45519 | F13: 0.64583333 | G13: No Show | H13: =IFERROR(HOUR(F13),"N/A") -> 15 | I13: =IFERROR(TEXT(E13,"dddd"),"N/A") -> Thursday
A14: N/A | B14: P83760 | C14: D1 | D14: Pediatric | E14: 45305 | F14: N/A | G14: Cancelled | H14: =IFERROR(HOUR(F14),"N/A") -> N/A | I14: =IFERROR(TEXT(E14,"dddd"),"N/A") -> Sunday
A15: A1132 | B15: P41254 | C15: D23 | D15: Cardiology | E15: 45344 | F15: 0.33333333 | G15: Completed | H15: =IFERROR(HOUR(F15),"N/A") -> 8 | I15: =IFERROR(TEXT(E15,"dddd"),"N/A") -> Thursday
A16: A6499 | B16: P73818 | C16: D6 | D16: Orthopedics | E16: 45311 | F16: 0.75 | G16: Rescheduled | H16: =IFERROR(HOUR(F16),"N/A") -> 18 | I16: =IFERROR(TEXT(E16,"dddd"),"N/A") -> Saturday
A17: A2196 | B17: P79312 | C17: D14 | D17: Neurology | E17: 45589 | F17: 0.625 | G17: Completed | H17: =IFERROR(HOUR(F17),"N/A") -> 15 | I17: =IFERROR(TEXT(E17,"dddd"),"N/A") -> Thursday
A18: A7135 | B18: P82827 | C18: D23 | D18: Neurology | E18: 45615 | F18: 0.60416667 | G18: Completed | H18: =IFERROR(HOUR(F18),"N/A") -> 14 | I18: =IFERROR(TEXT(E18,"dddd"),"N/A") -> Tuesday
A19: A8788 | B19: P25878 | C19: D28 | D19: Pediatric | E19: 45521 | F19: 0.66666667 | G19: Cancelled | H19: =IFERROR(HOUR(F19),"N/A") -> 16 | I19: =IFERROR(TEXT(E19,"dddd"),"N/A") -> Saturday
A20: A1284 | B20: P93291 | C20: D6 | D20: Neurology | E20: 45476 | F20: 0.75 | G20: Rescheduled | H20: =IFERROR(HOUR(F20),"N/A") -> 18 | I20: =IFERROR(TEXT(E20,"dddd"),"N/A") -> Wednesday
A21: A7527 | B21: P14299 | C21: D29 | D21: Cardiology | E21: 45652 | F21: 0.52083333 | G21: Cancelled | H21: =IFERROR(HOUR(F21),"N/A") -> 12 | I21: =IFERROR(TEXT(E21,"dddd"),"N/A") -> Thursday
A22: A5514 | B22: P90461 | C22: D15 | D22: Oncology | E22: 45640 | F22: 0.54166667 | G22: Cancelled | H22: =IFERROR(HOUR(F22),"N/A") -> 13 | I22: =IFERROR(TEXT(E22,"dddd"),"N/A") -> Saturday
A23: A4853 | B23: P77174 | C23: D11 | D23: Pediatric | E23: 45635 | F23: 0.39583333 | G23: Rescheduled | H23: =IFERROR(HOUR(F23),"N/A") -> 9 | I23: =IFERROR(TEXT(E23,"dddd"),"N/A") -> Monday
A24: A4504 | B24: P38694 | C24: D14 | D24: General Medicine | E24: 45644 | F24: 0.41666667 | G24: No Show | H24: =IFERROR(HOUR(F24),"N/A") -> 10 | I24: =IFERROR(TEXT(E24,"dddd"),"N/A") -> Wednesday
A25: A2106 | B25: P45916 | C25: D25 | D25: General Medicine | E25: 45641 | F25: 0.75 | G25: Rescheduled | H25: =IFERROR(HOUR(F25),"N/A") -> 18 | I25: =IFERROR(TEXT(E25,"dddd"),"N/A") -> Sunday
A26: N/A | B26: P98707 | C26: D20 | D26: General Medicine | E26: N/A | F26: 0.54166667 | G26: N/A | H26: =IFERROR(HOUR(F26),"N/A") -> 13 | I26: =IFERROR(TEXT(E26,"dddd"),"N/A") -> N/A
A27: A6156 | B27: P68619 | C27: D11 | D27: Pediatric | E27: 45558 | F27: 0.75 | G27: Completed | H27: =IFERROR(HOUR(F27),"N/A") -> 18 | I27: =IFERROR(TEXT(E27,"dddd"),"N/A") -> Monday
A28: A2963 | B28: P11071 | C28: D13 | D28: Orthopedics | E28: 45486 | F28: 0.77083333 | G28: Cancelled | H28: =IFERROR(HOUR(F28),"N/A") -> 18 | I28: =IFERROR(TEXT(E28,"dddd"),"N/A") -> Saturday
A29: A1511 | B29: P18878 | C29: D27 | D29: Pediatric | E29: 45322 | F29: 0.75 | G29: No Show | H29: =IFERROR(HOUR(F29),"N/A") -> 18 | I29: =IFERROR(TEXT(E29,"dddd"),"N/A") -> Wednesday
A30: A1949 | B30: P88817 | C30: D28 | D30: Pediatric | E30: 45520 | F30: 0.66666667 | G30: Cancelled | H30: =IFERROR(HOUR(F30),"N/A") -> 16 | I30: =IFERROR(TEXT(E30,"dddd"),"N/A") -> Friday
A31: A9088 | B31: P70452 | C31: D7 | D31: Neurology | E31: 45622 | F31: 0.41666667 | G31: No Show | H31: =IFERROR(HOUR(F31),"N/A") -> 10 | I31: =IFERROR(TEXT(E31,"dddd"),"N/A") -> Tuesday
A32: A1384 | B32: P79213 | C32: D13 | D32: General Medicine | E32: 45642 | F32: 0.35416667 | G32: Rescheduled | H32: =IFERROR(HOUR(F32),"N/A") -> 8 | I32: =IFERROR(TEXT(E32,"dddd"),"N/A") -> Monday
A33: A4140 | B33: P92292 | C33: D17 | D33: Orthopedics | E33: 45384 | F33: 0.72916667 | G33: No Show | H33: =IFERROR(HOUR(F33),"N/A") -> 17 | I33: =IFERROR(TEXT(E33,"dddd"),"N/A") -> Tuesday
A34: A6170 | B34: P46858 | C34: D17 | D34: Oncology | E34: 45446 | F34: 0.64583333 | G34: Rescheduled | H34: =IFERROR(HOUR(F34),"N/A") -> 15 | I34: =IFERROR(TEXT(E34,"dddd"),"N/A") -> Monday
A35: A5704 | B35: P10337 | C35: D12 | D35: Neurology | E35: 45383 | F35: 0.41666667 | G35: Cancelled | H35: =IFERROR(HOUR(F35),"N/A") -> 10 | I35: =IFERROR(TEXT(E35,"dddd"),"N/A") -> Monday
A36: A1762 | B36: P76416 | C36: D26 | D36: Oncology | E36: 45646 | F36: 0.5625 | G36: No Show | H36: =IFERROR(HOUR(F36),"N/A") -> 13 | I36: =IFERROR(TEXT(E36,"dddd"),"N/A") -> Friday
A37: A3377 | B37: P47558 | C37: D30 | D37: Orthopedics | E37: 45647 | F37: 0.6875 | G37: No Show | H37: =IFERROR(HOUR(F37),"N/A") -> 16 | I37: =IFERROR(TEXT(E37,"dddd"),"N/A") -> Saturday
A38: A7484 | B38: P10851 | C38: D11 | D38: General Medicine | E38: 45416 | F38: 0.6875 | G38: Completed | H38: =IFERROR(HOUR(F38),"N/A") -> 16 | I38: =IFERROR(TEXT(E38,"dddd"),"N/A") -> Saturday
... A57: A3495 | B57: P27259 | C57: D3 | D57: Neurology | E57: 45551 | F57: 0.64583333 | G57: Cancelled | H57: =IFERROR(HOUR(F57),"N/A") -> 15 | I57: =IFERROR(TEXT(E57,"dddd"),"N/A") -> Monday
A58: N/A | B58: P86378 | C58: D19 | D58: Neurology | E58: N/A | F58: N/A | G58: N/A | H58: =IFERROR(HOUR(F58),"N/A") -> N/A | I58: =IFERROR(TEXT(E58,"dddd"),"N/A") -> N/A
...

Sheet Cleaned_Feedback
A1: FeedbackID | B1: PatientID | C1: Department | D1: Feedback Score | E1: Comments | F1: WaitTime( in min)
A2: F1000 | B2: P99601 | C2: Cardiology | D2: 4 | E2: Delayed response | F2: 45
A3: F1001 | B3: P36565 | C3: Orthopedics | D3: 3 | E3: Needs improvement | F3: 45
A4: F1002 | B4: P99601 | C4: N/A | D4: 6.27 | E4: Excellent care | F4: 30
A5: F1003 | B5: P67499 | C5: Neurology | D5: 9 | E5: Amazing team | F5: 30
A6: F1004 | B6: P49994 | C6: Pediatric | D6: 8 | E6: Great doctors | F6: 45
A7: F1005 | B7: P31843 | C7: Pediatric | D7: 5 | E7: Satisfactory | F7: 45
A8: F1006 | B8: P63392 | C8: Neurology | D8: 4 | E8: Delayed response | F8: 45
A9: F1007 | B9: P66658 | C9: Neurology | D9: 7 | E9: Child-friendly staff | F9: 45
A10: F1008 | B10: P95953 | C10: Cardiology | D10: 7 | E10: Child-friendly staff | F10: 45
A11: F1009 | B11: P80770 | C11: Orthopedics | D11: 4 | E11: Delayed response | F11: 45
A12: F1010 | B12: P29680 | C12: Orthopedics | D12: 4 | E12: Room cleanliness issue | F12: 45
A13: F1011 | B13: P93978 | C13: Orthopedics | D13: 3 | E13: Long wait times | F13: 45
... A18: F1016 | B18: P82827 | C18: Neurology | D18: 5 | E18: Average | F18: 45
A19: F1017 | B19: P25878 | C19: N/A | D19: 6.27 | E19: Helpful staff | F19: N/A
A20: F1018 | B20: P93291 | C20: Neurology | D20: 8 | E20: Efficient process | F20: 45
A21: F1019 | B21: P14299 | C21: Cardiology | D21: 8 | E21: Great doctors | F21: 45
A22: F1020 | B22: P90461 | C22: Oncology | D22: 3 | E22: Needs improvement | F22: 45
A23: F1021 | B23: P77174 | C23: Pediatric | D23: 4 | E23: Delayed response | F23: 45
A24: F1022 | B24: P38694 | C24: General Medicine | D24: 7 | E24: Child-friendly staff | F24: 45
A25: F1023 | B25: P45916 | C25: General Medicine | D25: 4 | E25: Delayed response | F25: 45
A26: F1024 | B26: P67499 | C26: General Medicine | D26: 9 | E26: Highly recommended | F26: 30
A27: F1025 | B27: P68619 | C27: Pediatric | D27: 4 | E27: Delayed response | F27: 45
A28: F1026 | B28: P11071 | C28: Orthopedics | D28: 7 | E28: Child-friendly staff | F28: 45
A29: F1027 | B29: P18878 | C29: Pediatric | D29: 7 | E29: Satisfactory | F29: 45
A30: F1028 | B30: P88817 | C30: Pediatric | D30: 3 | E30: Needs improvement | F30: 45
A31: F1029 | B31: P70452 | C31: Neurology | D31: 9 | E31: Excellent care | F31: 30
... A104: F1103 | B104: P29322 | C104: Neurology | D104: 7 | E104: Satisfactory | F104: 45
A105: F1104 | B105: P64103 | C105: N/A | D105: 6.27 | E105: N/A | F105: N/A
A106: F1105 | B106: P93372 | C106: General Medicine | D106: 4 | E106: Delayed response | F106: 45
A107: F1106 | B107: P33026 | C107: Orthopedics | D107: 8 | E107: Great doctors | F107: 45
A108: F1107 | B108: P47436 | C108: Cardiology | D108: 8 | E108: Efficient process | F108: 45
A109: F1108 | B109: P48965 | C109: Oncology | D109: 9 | E109: Highly recommended | F109: 30
A110: F1109 | B110: P20771 | C110: Pediatric | D110: 6 | E110: Very good | F110: 45
A111: F1110 | B111: P32966 | C111: Pediatric | D111: 6 | E111: Very good | F111: 45
A112: F1111 | B112: P65077 | C112: General Medicine | D112: 4 | E112: Delayed response | F112: 45
A113: F1112 | B113: P30147 | C113: Oncology | D113: 3 | E113: Long wait times | F113: 45
A114: F1113 | B114: P28668 | C114: Pediatric | D114: 4 | E114: Delayed response | F114: 45
A115: F1114 | B115: P54890 | C115: Oncology | D115: 4 | E115: Room cleanliness issue | F115: 45
A116: F1115 | B116: P77589 | C116: Pediatric | D116: 3 | E116: Long wait times | F116: 45
...

Sheet Cleaned_Resource
A1: ResourceID | B1: Department | C1: ResourceType | D1: UsageHours | E1: Date | F1: Availability
A2: R5487 | B2: Cardiology | C2: Nurse | D2: 2 | E2: 45501 | F2: Available
A3: R8097 | B3: Orthopedics | C3: Doctor | D3: 0 | E3: 45545 | F3: Unavailable
A4: R2557 | B4: General Medicine | C4: Room | D4: 0 | E4: 45643 | F4: Under Maintenance
A5: R9024 | B5: Neurology | C5: Doctor | D5: 9 | E5: 45482 | F5: Available
A6: R9181 | B6: N/A | C6: Room | D6: 1 | E6: N/A | F6: Available
A7: R2629 | B7: Oncology | C7: Doctor | D7: 4 | E7: 45357 | F7: Available
A8: R1317 | B8: Cardiology | C8: Nurse | D8: 5 | E8: 45383 | F8: Available
A9: R9640 | B9: Neurology | C9: Room | D9: 1 | E9: 45581 | F9: Available
A10: R1787 | B10: Oncology | C10: Doctor | D10: 8 | E10: 45558 | F10: Available
A11: R9426 | B11: Cardiology | C11: Technician | D11: 5 | E11: 45395 | F11: In Use
A12: R1606 | B12: General Medicine | C12: Nurse | D12: 8 | E12: 45460 | F12: Available
A13: R3242 | B13: Pediatric | C13: Doctor | D13: 6 | E13: 45519 | F13: Available
A14: R6893 | B14: Neurology | C14: Doctor | D14: 3 | E14: 45416 | F14: Available
A15: R3237 | B15: Orthopedics | C15: Nurse | D15: 4 | E15: 45344 | F15: Available
A16: R5274 | B16: General Medicine | C16: Doctor | D16: 7 | E16: 45311 | F16: Available
A17: R1039 | B17: Neurology | C17: Technician | D17: 5 | E17: 45589 | F17: Available
A18: R5597 | B18: Neurology | C18: Nurse | D18: 0 | E18: 45615 | F18: Unavailable
... A21: R5074 | B21: Oncology | C21: Room | D21: 4 | E21: 45652 | F21: In Use
A22: R3855 | B22: Orthopedics | C22: N/A | D22: 0 | E22: N/A | F22: Unavailable
A23: R8405 | B23: Neurology | C23: Technician | D23: 5 | E23: 45635 | F23: Available
A24: R5984 | B24: Orthopedics | C24: Equipment | D24: 3 | E24: 45644 | F24: In Use
A25: R6968 | B25: General Medicine | C25: Doctor | D25: 1 | E25: 45641 | F25: Available
A26: R7116 | B26: Cardiology | C26: Technician | D26: 8 | E26: 45392 | F26: Available
A27: R4399 | B27: General Medicine | C27: Room | D27: 0 | E27: 45558 | F27: Under Maintenance
A28: R6261 | B28: Neurology | C28: Equipment | D28: 0 | E28: 45486 | F28: Under Maintenance
A29: R9923 | B29: Cardiology | C29: Technician | D29: 8 | E29: 45322 | F29: Available
A30: R6097 | B30: Neurology | C30: Nurse | D30: 9 | E30: 45520 | F30: Available
A31: R1624 | B31: Oncology | C31: Room | D31: 2 | E31: 45622 | F31: In Use
A32: R6385 | B32: Oncology | C32: Doctor | D32: 0 | E32: 45642 | F32: Unavailable
A33: R2625 | B33: Neurology | C33: Equipment | D33: 0 | E33: 45384 | F33: Under Maintenance
A34: R3097 | B34: Orthopedics | C34: Room | D34: 0 | E34: 45446 | F34: Under Maintenance
... A44: R2833 | B44: General Medicine | C44: Equipment | D44: 3 | E44: 45507 | F44: In Use
A45: N/A | B45: Oncology | C45: N/A | D45: 1 | E45: N/A | F45: Available
A46: R5799 | B46: General Medicine | C46: Nurse | D46: 9 | E46: 45313 | F46: Available
A47: R2825 | B47: Pediatric | C47: Technician | D47: 8 | E47: 45347 | F47: Available
A48: R5252 | B48: Pediatric | C48: Nurse | D48: 7 | E48: 45466 | F48: Available
A49: R7354 | B49: Pediatric | C49: Doctor | D49: 9 | E49: 45350 | F49: Available
A50: R2717 | B50: Cardiology | C50: Technician | D50: 3 | E50: 45590 | F50: Available
A51: R3782 | B51: Pediatric | C51: Doctor | D51: 7 | E51: 45324 | F51: In Use
...

Sheet Combined_Dataset
A1: Patient ID | B1: Appointment Date | C1: Time | D1: Department | E1: Feedback Score | F1: Comments | G1: Wait Time (in min) | H1: Satisfaction Level | I1: Hour
A2: =Cleaned_Feedback!B2 -> P99601 | B2: =IFERROR(VLOOKUP(A2,Cleaned_Appointment!$B:$G,4,FALSE()),"N/A") -> 45643 | C2: =IFERROR(VLOOKUP(A2,Cleaned_Appointment!$B:$G,5,FALSE()),"N/A") -> 0.625 | D2: =Cleaned_Feedback!C2 -> Cardiology | E2: =Cleaned_Feedback!D2 -> 4 | F2: =Cleaned_Feedback!E2 -> Delayed response | G2: =Cleaned_Feedback!F2 -> 45 | H2: =IF(ISNUMBER(E2),IF(E2>=4,"High","Low"),"N/A") -> High | I2: =IFERROR(HOUR(C2),"N/A") -> 15
A3: =Cleaned_Feedback!B3 -> P36565 | B3: =IFERROR(VLOOKUP(A3,Cleaned_Appointment!$B:$G,4,FALSE()),"N/A") -> 45535 | C3: =IFERROR(VLOOKUP(A3,Cleaned_Appointment!$B:$G,5,FALSE()),"N/A") -> 0.45833333 | D3: =Cleaned_Feedback!C3 -> Orthopedics | E3: =Cleaned_Feedback!D3 -> 3 | F3: =Cleaned_Feedback!E3 -> Needs improvement | G3: =Cleaned_Feedback!F3 -> 45 | H3: =IF(ISNUMBER(E3),IF(E3>=4,"High","Low"),"N/A") -> Low | I3: =IFERROR(HOUR(C3),"N/A") -> 11
A4: =Cleaned_Feedback!B4 -> P99601 | B4: =IFERROR(VLOOKUP(A4,Cleaned_Appointment!$B:$G,4,FALSE()),"N/A") -> 45643 | C4: =IFERROR(VLOOKUP(A4,Cleaned_Appointment!$B:$G,5,FALSE()),"N/A") -> 0.625 | D4: =Cleaned_Feedback!C4 -> N/A | E4: =Cleaned_Feedback!D4 -> 6.27 | F4: =Cleaned_Feedback!E4 -> Excellent care | G4: =Cleaned_Feedback!F4 -> 30 | H4: =IF(ISNUMBER(E4),IF(E4>=4,"High","Low"),"N/A") -> High | I4: =IFERROR(HOUR(C4),"N/A") -> 15
A5: =Cleaned_Feedback!B5 -> P67499 | B5: =IFERROR(VLOOKUP(A5,Cleaned_Appointment!$B:$G,4,FALSE()),"N/A") -> 45350 | C5: =IFERROR(VLOOKUP(A5,Cleaned_Appointment!$B:$G,5,FALSE()),"N/A") -> 0.77083333 | D5: =Cleaned_Feedback!C5 -> Neurology | E5: =Cleaned_Feedback!D5 -> 9 | F5: =Cleaned_Feedback!E5 -> Amazing team | G5: =Cleaned_Feedback!F5 -> 30 | H5: =IF(ISNUMBER(E5),IF(E5>=4,"High","Low"),"N/A") -> High | I5: =IFERROR(HOUR(C5),"N/A") -> 18
A6: =Cleaned_Feedback!B6 -> P49994 | B6: =IFERROR(VLOOKUP(A6,Cleaned_Appointment!$B:$G,4,FALSE()),"N/A") -> 45594 | C6: =IFERROR(VLOOKUP(A6,Cleaned_Appointment!$B:$G,5,FALSE()),"N/A") -> 0.70833333 | D6: =Cleaned_Feedback!C6 -> Pediatric | E6: =Cleaned_Feedback!D6 -> 8 | F6: =Cleaned_Feedback!E6 -> Great doctors | G6: =Cleaned_Feedback!F6 -> 45 | H6: =IF(ISNUMBER(E6),IF(E6>=4,"High","Low"),"N/A") -> High | I6: =IFERROR(HOUR(C6),"N/A") -> 17
A7: =Cleaned_Feedback!B7 -> P31843 | B7: =IFERROR(VLOOKUP(A7,Cleaned_Appointment!$B:$G,4,FALSE()),"N/A") -> 45646 | C7: =IFERROR(VLOOKUP(A7,Cleaned_Appointment!$B:$G,5,FALSE()),"N/A") -> 0.4375 | D7: =Cleaned_Feedback!C7 -> Pediatric | E7: =Cleaned_Feedback!D7 -> 5 | F7: =Cleaned_Feedback!E7 -> Satisfactory | G7: =Cleaned_Feedback!F7 -> 45 | H7: =IF(ISNUMBER(E7),IF(E7>=4,"High","Low"),"N/A") -> High | I7: =IFERROR(HOUR(C7),"N/A") -> 10
A8: =Cleaned_Feedback!B8 -> P63392 | B8: =IFERROR(VLOOKUP(A8,Cleaned_Appointment!$B:$G,4,FALSE()),"N/A") -> 45324 | C8: =IFERROR(VLOOKUP(A8,Cleaned_Appointment!$B:$G,5,FALSE()),"N/A") -> 0.625 | D8: =Cleaned_Feedback!C8 -> Neurology | E8: =Cleaned_Feedback!D8 -> 4 | F8: =Cleaned_Feedback!E8 -> Delayed response | G8: =Cleaned_Feedback!F8 -> 45 | H8: =IF(ISNUMBER(E8),IF(E8>=4,"High","Low"),"N/A") -> High | I8: =IFERROR(HOUR(C8),"N/A") -> 15
A9: =Cleaned_Feedback!B9 -> P66658 | B9: =IFERROR(VLOOKUP(A9,Cleaned_Appointment!$B:$G,4,FALSE()),"N/A") -> 45634 | C9: =IFERROR(VLOOKUP(A9,Cleaned_Appointment!$B:$G,5,FALSE()),"N/A") -> 0.60416667 | D9: =Cleaned_Feedback!C9 -> Neurology | E9: =Cleaned_Feedback!D9 -> 7 | F9: =Cleaned_Feedback!E9 -> Child-friendly staff | G9: =Cleaned_Feedback!F9 -> 45 | H9: =IF(ISNUMBER(E9),IF(E9>=4,"High","Low"),"N/A") -> High | I9: =IFERROR(HOUR(C9),"N/A") -> 14
A10: =Cleaned_Feedback!B10 -> P95953 | B10: =IFERROR(VLOOKUP(A10,Cleaned_Appointment!$B:$G,4,FALSE()),"N/A") -> 45325 | C10: =IFERROR(VLOOKUP(A10,Cleaned_Appointment!$B:$G,5,FALSE()),"N/A") -> 0.39583333 | D10: =Cleaned_Feedback!C10 -> Cardiology | E10: =Cleaned_Feedback!D10 -> 7 | F10: =Cleaned_Feedback!E10 -> Child-friendly staff | G10: =Cleaned_Feedback!F10 -> 45 | H10: =IF(ISNUMBER(E10),IF(E10>=4,"High","Low"),"N/A") -> High | I10: =IFERROR(HOUR(C10),"N/A") -> 9
A11: =Cleaned_Feedback!B11 -> P80770 | B11: =IFERROR(VLOOKUP(A11,Cleaned_Appointment!$B:$G,4,FALSE()),"N/A") -> 45368 | C11: =IFERROR(VLOOKUP(A11,Cleaned_Appointment!$B:$G,5,FALSE()),"N/A") -> 0.375 | D11: =Cleaned_Feedback!C11 -> Orthopedics | E11: =Cleaned_Feedback!D11 -> 4 | F11: =Cleaned_Feedback!E11 -> Delayed response | G11: =Cleaned_Feedback!F11 -> 45 | H11: =IF(ISNUMBER(E11),IF(E11>=4,"High","Low"),"N/A") -> High | I11: =IFERROR(HOUR(C11),"N/A") -> 9
A12: =Cleaned_Feedback!B12 -> P29680 | B12: =IFERROR(VLOOKUP(A12,Cleaned_Appointment!$B:$G,4,FALSE()),"N/A") -> 45460 | C12: =IFERROR(VLOOKUP(A12,Cleaned_Appointment!$B:$G,5,FALSE()),"N/A") -> 0.35416667 | D12: =Cleaned_Feedback!C12 -> Orthopedics | E12: =Cleaned_Feedback!D12 -> 4 | F12: =Cleaned_Feedback!E12 -> Room cleanliness issue | G12: =Cleaned_Feedback!F12 -> 45 | H12: =IF(ISNUMBER(E12),IF(E12>=4,"High","Low"),"N/A") -> High | I12: =IFERROR(HOUR(C12),"N/A") -> 8
A13: =Cleaned_Feedback!B13 -> P93978 | B13: =IFERROR(VLOOKUP(A13,Cleaned_Appointment!$B:$G,4,FALSE()),"N/A") -> 45519 | C13: =IFERROR(VLOOKUP(A13,Cleaned_Appointment!$B:$G,5,FALSE()),"N/A") -> 0.64583333 | D13: =Cleaned_Feedback!C13 -> Orthopedics | E13: =Cleaned_Feedback!D13 -> 3 | F13: =Cleaned_Feedback!E13 -> Long wait times | G13: =Cleaned_Feedback!F13 -> 45 | H13: =IF(ISNUMBER(E13),IF(E13>=4,"High","Low"),"N/A") -> Low | I13: =IFERROR(HOUR(C13),"N/A") -> 15
... A200: =Cleaned_Feedback!B200 -> N/A | B200: =IFERROR(VLOOKUP(A200,Cleaned_Appointment!$B:$G,4,FALSE()),"N/A") -> N/A | C200: =IFERROR(VLOOKUP(A200,Cleaned_Appointment!$B:$G,5,FALSE()),"N/A") -> N/A | D200: =Cleaned_Feedback!C200 -> N/A | E200: =Cleaned_Feedback!D200 -> 6.27 | F200: =Cleaned_Feedback!E200 -> N/A | G200: =Cleaned_Feedback!F200 -> N/A | H200: =IF(ISNUMBER(E200),IF(E200>=4,"High","Low"),"N/A") -> High | I200: =IFERROR(HOUR(C200),"N/A") -> N/A

Sheet Pivot_Appointments
A1: Appointments by Department and Hour of Day
A3: Department | B3: 8:00 | C3: 9:00 | D3: 10:00 | E3: 11:00 | F3: 12:00 | G3: 13:00 | H3: 14:00 | I3: 15:00 | J3: 16:00 | K3: 17:00 | L3: 18:00 | M3: N/A | N3: Total
A4: Cardiology | B4: =COUNTIFS(Cleaned_Appointment!$D$2:$D$202,"Cardiology",Cleaned_Appointment!$H$2:$H$202,8) -> 5 | C4: =COUNTIFS(Cleaned_Appointment!$D$2:$D$202,"Cardiology",Cleaned_Appointment!$H$2:$H$202,9) -> 2 | D4: =COUNTIFS(Cleaned_Appointment!$D$2:$D$202,"Cardiology",Cleaned_Appointment!$H$2:$H$202,10) -> 0 | E4: =COUNTIFS(Cleaned_Appointment!$D$2:$D$202,"Cardiology",Cleaned_Appointment!$H$2:$H$202,11) -> 3 | F4: =COUNTIFS(Cleaned_Appointment!$D$2:$D$202,"Cardiology",Cleaned_Appointment!$H$2:$H$202,12) -> 6 | G4: =COUNTIFS(Cleaned_Appointment!$D$2:$D$202,"Cardiology",Cleaned_Appointment!$H$2:$H$202,13) -> 2 | H4: =COUNTIFS(Cleaned_Appointment!$D$2:$D$202,"Cardiology",Cleaned_Appointment!$H$2:$H$202,14) -> 4 | I4: =COUNTIFS(Cleaned_Appointment!$D$2:$D$202,"Cardiology",Cleaned_Appointment!$H$2:$H$202,15) -> 7 | J4: =COUNTIFS(Cleaned_Appointment!$D$2:$D$202,"Cardiology",Cleaned_Appointment!$H$2:$H$202,16) -> 2 | K4: =COUNTIFS(Cleaned_Appointment!$D$2:$D$202,"Cardiology",Cleaned_Appointment!$H$2:$H$202,17) -> 4 | L4: =COUNTIFS(Cleaned_Appointment!$D$2:$D$202,"Cardiology",Cleaned_Appointment!$H$2:$H$202,18) -> 2 | M4: =COUNTIFS(Cleaned_Appointment!$D$2:$D$202,"Cardiology",Cleaned_Appointment!$H$2:$H$202,"N/A") -> 1 | N4: =SUM(B4:M4) -> 38
A5: General Medicine | B5: =COUNTIFS(Cleaned_Appointment!$D$2:$D$202,"General Medicine",Cleaned_Appointment!$H$2:$H$202,8) -> 3 | C5: =COUNTIFS(Cleaned_Appointment!$D$2:$D$202,"General Medicine",Cleaned_Appointment!$H$2:$H$202,9) -> 2 | D5: =COUNTIFS(Cleaned_Appointment!$D$2:$D$202,"General Medicine",Cleaned_Appointment!$H$2:$H$202,10) -> 2 | E5: =COUNTIFS(Cleaned_Appointment!$D$2:$D$202,"General Medicine",Cleaned_Appointment!$H$2:$H$202,11) -> 2 | F5: =COUNTIFS(Cleaned_Appointment!$D$2:$D$202,"General Medicine",Cleaned_Appointment!$H$2:$H$202,12) -> 2 | G5: =COUNTIFS(Cleaned_Appointment!$D$2:$D$202,"General Medicine",Cleaned_Appointment!$H$2:$H$202,13) -> 3 | H5: =COUNTIFS(Cleaned_Appointment!$D$2:$D$202,"General Medicine",Cleaned_Appointment!$H$2:$H$202,14) -> 2 | I5: =COUNTIFS(Cleaned_Appointment!$D$2:$D$202,"General Medicine",Cleaned_Appointment!$H$2:$H$202,15) -> 1 | J5: =COUNTIFS(Cleaned_Appointment!$D$2:$D$202,"General Medicine",Cleaned_Appointment!$H$2:$H$202,16) -> 3 | K5: =COUNTIFS(Cleaned_Appointment!$D$2:$D$202,"General Medicine",Cleaned_Appointment!$H$2:$H$202,17) -> 2 | L5: =COUNTIFS(Cleaned_Appointment!$D$2:$D$202,"General Medicine",Cleaned_Appointment!$H$2:$H$202,18) -> 4 | M5: =COUNTIFS(Cleaned_Appointment!$D$2:$D$202,"General Medicine",Cleaned_Appointment!$H$2:$H$202,"N/A") -> 1 | N5: =SUM(B5:M5) -> 27
A6: Neurology | B6: =COUNTIFS(Cleaned_Appointment!$D$2:$D$202,"Neurology",Cleaned_Appointment!$H$2:$H$202,8) -> 3 | C6: =COUNTIFS(Cleaned_Appointment!$D$2:$D$202,"Neurology",Cleaned_Appointment!$H$2:$H$202,9) -> 1 | D6: =COUNTIFS(Cleaned_Appointment!$D$2:$D$202,"Neurology",Cleaned_Appointment!$H$2:$H$202,10) -> 5 | E6: =COUNTIFS(Cleaned_Appointment!$D$2:$D$202,"Neurology",Cleaned_Appointment!$H$2:$H$202,11) -> 4 | F6: =COUNTIFS(Cleaned_Appointment!$D$2:$D$202,"Neurology",Cleaned_Appointment!$H$2:$H$202,12) -> 6 | G6: =COUNTIFS(Cleaned_Appointment!$D$2:$D$202,"Neurology",Cleaned_Appointment!$H$2:$H$202,13) -> 0 | H6: =COUNTIFS(Cleaned_Appointment!$D$2:$D$202,"Neurology",Cleaned_Appointment!$H$2:$H$202,14) -> 2 | I6: =COUNTIFS(Cleaned_Appointment!$D$2:$D$202,"Neurology",Cleaned_Appointment!$H$2:$H$202,15) -> 4 | J6: =COUNTIFS(Cleaned_Appointment!$D$2:$D$202,"Neurology",Cleaned_Appointment!$H$2:$H$202,16) -> 2 | K6: =COUNTIFS(Cleaned_Appointment!$D$2:$D$202,"Neurology",Cleaned_Appointment!$H$2:$H$202,17) -> 2 | L6: =COUNTIFS(Cleaned_Appointment!$D$2:$D$202,"Neurology",Cleaned_Appointment!$H$2:$H$202,18) -> 5 | M6: =COUNTIFS(Cleaned_Appointment!$D$2:$D$202,"Neurology",Cleaned_Appointment!$H$2:$H$202,"N/A") -> 1 | N6: =SUM(B6:M6) -> 35
A7: Oncology | B7: =COUNTIFS(Cleaned_Appointment!$D$2:$D$202,"Oncology",Cleaned_Appointment!$H$2:$H$202,8) -> 1 | C7: =COUNTIFS(Cleaned_Appointment!$D$2:$D$202,"Oncology",Cleaned_Appointment!$H$2:$H$202,9) -> 3 | D7: =COUNTIFS(Cleaned_Appointment!$D$2:$D$202,"Oncology",Cleaned_Appointment!$H$2:$H$202,10) -> 1 | E7: =COUNTIFS(Cleaned_Appointment!$D$2:$D$202,"Oncology",Cleaned_Appointment!$H$2:$H$202,11) -> 3 | F7: =COUNTIFS(Cleaned_Appointment!$D$2:$D$202,"Oncology",Cleaned_Appointment!$H$2:$H$202,12) -> 2 | G7: =COUNTIFS(Cleaned_Appointment!$D$2:$D$202,"Oncology",Cleaned_Appointment!$H$2:$H$202,13) -> 2 | H7: =COUNTIFS(Cleaned_Appointment!$D$2:$D$202,"Oncology",Cleaned_Appointment!$H$2:$H$202,14) -> 0 | I7: =COUNTIFS(Cleaned_Appointment!$D$2:$D$202,"Oncology",Cleaned_Appointment!$H$2:$H$202,15) -> 3 | J7: =COUNTIFS(Cleaned_Appointment!$D$2:$D$202,"Oncology",Cleaned_Appointment!$H$2:$H$202,16) -> 6 | K7: =COUNTIFS(Cleaned_Appointment!$D$2:$D$202,"Oncology",Cleaned_Appointment!$H$2:$H$202,17) -> 3 | L7: =COUNTIFS(Cleaned_Appointment!$D$2:$D$202,"Oncology",Cleaned_Appointment!$H$2:$H$202,18) -> 5 | M7: =COUNTIFS(Cleaned_Appointment!$D$2:$D$202,"Oncology",Cleaned_Appointment!$H$2:$H$202,"N/A") -> 3 | N7: =SUM(B7:M7) -> 32
A8: Orthopedics | B8: =COUNTIFS(Cleaned_Appointment!$D$2:$D$202,"Orthopedics",Cleaned_Appointment!$H$2:$H$202,8) -> 2 | C8: =COUNTIFS(Cleaned_Appointment!$D$2:$D$202,"Orthopedics",Cleaned_Appointment!$H$2:$H$202,9) -> 2 | D8: =COUNTIFS(Cleaned_Appointment!$D$2:$D$202,"Orthopedics",Cleaned_Appointment!$H$2:$H$202,10) -> 1 | E8: =COUNTIFS(Cleaned_Appointment!$D$2:$D$202,"Orthopedics",Cleaned_Appointment!$H$2:$H$202,11) -> 3 | F8: =COUNTIFS(Cleaned_Appointment!$D$2:$D$202,"Orthopedics",Cleaned_Appointment!$H$2:$H$202,12) -> 1 | G8: =COUNTIFS(Cleaned_Appointment!$D$2:$D$202,"Orthopedics",Cleaned_Appointment!$H$2:$H$202,13) -> 2 | H8: =COUNTIFS(Cleaned_Appointment!$D$2:$D$202,"Orthopedics",Cleaned_Appointment!$H$2:$H$202,14) -> 2 | I8: =COUNTIFS(Cleaned_Appointment!$D$2:$D$202,"Orthopedics",Cleaned_Appointment!$H$2:$H$202,15) -> 4 | J8: =COUNTIFS(Cleaned_Appointment!$D$2:$D$202,"Orthopedics",Cleaned_Appointment!$H$2:$H$202,16) -> 2 | K8: =COUNTIFS(Cleaned_Appointment!$D$2:$D$202,"Orthopedics",Cleaned_Appointment!$H$2:$H$202,17) -> 5 | L8: =COUNTIFS(Cleaned_Appointment!$D$2:$D$202,"Orthopedics",Cleaned_Appointment!$H$2:$H$202,18) -> 6 | M8: =COUNTIFS(Cleaned_Appointment!$D$2:$D$202,"Orthopedics",Cleaned_Appointment!$H$2:$H$202,"N/A") -> 0 | N8: =SUM(B8:M8) -> 30
A9: Pediatric | B9: =COUNTIFS(Cleaned_Appointment!$D$2:$D$202,"Pediatric",Cleaned_Appointment!$H$2:$H$202,8) -> 4 | C9: =COUNTIFS(Cleaned_Appointment!$D$2:$D$202,"Pediatric",Cleaned_Appointment!$H$2:$H$202,9) -> 5 | D9: =COUNTIFS(Cleaned_Appointment!$D$2:$D$202,"Pediatric",Cleaned_Appointment!$H$2:$H$202,10) -> 5 | E9: =COUNTIFS(Cleaned_Appointment!$D$2:$D$202,"Pediatric",Cleaned_Appointment!$H$2:$H$202,11) -> 2 | F9: =COUNTIFS(Cleaned_Appointment!$D$2:$D$202,"Pediatric",Cleaned_Appointment!$H$2:$H$202,12) -> 1 | G9: =COUNTIFS(Cleaned_Appointment!$D$2:$D$202,"Pediatric",Cleaned_Appointment!$H$2:$H$202,13) -> 3 | H9: =COUNTIFS(Cleaned_Appointment!$D$2:$D$202,"Pediatric",Cleaned_Appointment!$H$2:$H$202,14) -> 3 | I9: =COUNTIFS(Cleaned_Appointment!$D$2:$D$202,"Pediatric",Cleaned_Appointment!$H$2:$H$202,15) -> 0 | J9: =COUNTIFS(Cleaned_Appointment!$D$2:$D$202,"Pediatric",Cleaned_Appointment!$H$2:$H$202,16) -> 3 | K9: =COUNTIFS(Cleaned_Appointment!$D$2:$D$202,"Pediatric",Cleaned_Appointment!$H$2:$H$202,17) -> 4 | L9: =COUNTIFS(Cleaned_Appointment!$D$2:$D$202,"Pediatric",Cleaned_Appointment!$H$2:$H$202,18) -> 5 | M9: =COUNTIFS(Cleaned_Appointment!$D$2:$D$202,"Pediatric",Cleaned_Appointment!$H$2:$H$202,"N/A") -> 2 | N9: =SUM(B9:M9) -> 37
A10: N/A | B10: =COUNTIFS(Cleaned_Appointment!$D$2:$D$202,"N/A",Cleaned_Appointment!$H$2:$H$202,8) -> 0 | C10: =COUNTIFS(Cleaned_Appointment!$D$2:$D$202,"N/A",Cleaned_Appointment!$H$2:$H$202,9) -> 0 | D10: =COUNTIFS(Cleaned_Appointment!$D$2:$D$202,"N/A",Cleaned_Appointment!$H$2:$H$202,10) -> 0 | E10: =COUNTIFS(Cleaned_Appointment!$D$2:$D$202,"N/A",Cleaned_Appointment!$H$2:$H$202,11) -> 0 | F10: =COUNTIFS(Cleaned_Appointment!$D$2:$D$202,"N/A",Cleaned_Appointment!$H$2:$H$202,12) -> 0 | G10: =COUNTIFS(Cleaned_Appointment!$D$2:$D$202,"N/A",Cleaned_Appointment!$H$2:$H$202,13) -> 0 | H10: =COUNTIFS(Cleaned_Appointment!$D$2:$D$202,"N/A",Cleaned_Appointment!$H$2:$H$202,14) -> 0 | I10: =COUNTIFS(Cleaned_Appointment!$D$2:$D$202,"N/A",Cleaned_Appointment!$H$2:$H$202,15) -> 0 | J10: =COUNTIFS(Cleaned_Appointment!$D$2:$D$202,"N/A",Cleaned_Appointment!$H$2:$H$202,16) -> 0 | K10: =COUNTIFS(Cleaned_Appointment!$D$2:$D$202,"N/A",Cleaned_Appointment!$H$2:$H$202,17) -> 0 | L10: =COUNTIFS(Cleaned_Appointment!$D$2:$D$202,"N/A",Cleaned_Appointment!$H$2:$H$202,18) -> 0 | M10: =COUNTIFS(Cleaned_Appointment!$D$2:$D$202,"N/A",Cleaned_Appointment!$H$2:$H$202,"N/A") -> 2 | N10: =SUM(B10:M10) -> 2
A11: Total | B11: =SUM(B4:B10) -> 18 | C11: =SUM(C4:C10) -> 15 | D11: =SUM(D4:D10) -> 14 | E11: =SUM(E4:E10) -> 17 | F11: =SUM(F4:F10) -> 18 | G11: =SUM(G4:G10) -> 12 | H11: =SUM(H4:H10) -> 13 | I11: =SUM(I4:I10) -> 19 | ... N11: =SUM(N4:N10) -> 201

Sheet Pivot_Satisfaction
A1: Satisfaction Levels by Department
A3: Department | B3: High | C3: Low | D3: N/A | E3: Total
A4: Cardiology | B4: =COUNTIFS(Combined_Dataset!$D$2:$D$200,"Cardiology",Combined_Dataset!$H$2:$H$200,"High") -> 31 | C4: =COUNTIFS(Combined_Dataset!$D$2:$D$200,"Cardiology",Combined_Dataset!$H$2:$H$200,"Low") -> 2 | D4: =COUNTIFS(Combined_Dataset!$D$2:$D$200,"Cardiology",Combined_Dataset!$H$2:$H$200,"N/A") -> 0 | E4: =SUM(B4:D4) -> 33
A5: General Medicine | B5: =COUNTIFS(Combined_Dataset!$D$2:$D$200,"General Medicine",Combined_Dataset!$H$2:$H$200,"High") -> 21 | C5: =COUNTIFS(Combined_Dataset!$D$2:$D$200,"General Medicine",Combined_Dataset!$H$2:$H$200,"Low") -> 5 | D5: =COUNTIFS(Combined_Dataset!$D$2:$D$200,"General Medicine",Combined_Dataset!$H$2:$H$200,"N/A") -> 0 | E5: =SUM(B5:D5) -> 26
A6: Neurology | B6: =COUNTIFS(Combined_Dataset!$D$2:$D$200,"Neurology",Combined_Dataset!$H$2:$H$200,"High") -> 33 | C6: =COUNTIFS(Combined_Dataset!$D$2:$D$200,"Neurology",Combined_Dataset!$H$2:$H$200,"Low") -> 1 | D6: =COUNTIFS(Combined_Dataset!$D$2:$D$200,"Neurology",Combined_Dataset!$H$2:$H$200,"N/A") -> 0 | E6: =SUM(B6:D6) -> 34
A7: Oncology | B7: =COUNTIFS(Combined_Dataset!$D$2:$D$200,"Oncology",Combined_Dataset!$H$2:$H$200,"High") -> 26 | C7: =COUNTIFS(Combined_Dataset!$D$2:$D$200,"Oncology",Combined_Dataset!$H$2:$H$200,"Low") -> 6 | D7: =COUNTIFS(Combined_Dataset!$D$2:$D$200,"Oncology",Combined_Dataset!$H$2:$H$200,"N/A") -> 0 | E7: =SUM(B7:D7) -> 32
A8: Orthopedics | B8: =COUNTIFS(Combined_Dataset!$D$2:$D$200,"Orthopedics",Combined_Dataset!$H$2:$H$200,"High") -> 21 | C8: =COUNTIFS(Combined_Dataset!$D$2:$D$200,"Orthopedics",Combined_Dataset!$H$2:$H$200,"Low") -> 8 | D8: =COUNTIFS(Combined_Dataset!$D$2:$D$200,"Orthopedics",Combined_Dataset!$H$2:$H$200,"N/A") -> 0 | E8: =SUM(B8:D8) -> 29
A9: Pediatric | B9: =COUNTIFS(Combined_Dataset!$D$2:$D$200,"Pediatric",Combined_Dataset!$H$2:$H$200,"High") -> 32 | C9: =COUNTIFS(Combined_Dataset!$D$2:$D$200,"Pediatric",Combined_Dataset!$H$2:$H$200,"Low") -> 5 | D9: =COUNTIFS(Combined_Dataset!$D$2:$D$200,"Pediatric",Combined_Dataset!$H$2:$H$200,"N/A") -> 0 | E9: =SUM(B9:D9) -> 37
A10: N/A | B10: =COUNTIFS(Combined_Dataset!$D$2:$D$200,"N/A",Combined_Dataset!$H$2:$H$200,"High") -> 8 | C10: =COUNTIFS(Combined_Dataset!$D$2:$D$200,"N/A",Combined_Dataset!$H$2:$H$200,"Low") -> 0 | D10: =COUNTIFS(Combined_Dataset!$D$2:$D$200,"N/A",Combined_Dataset!$H$2:$H$200,"N/A") -> 0 | E10: =SUM(B10:D10) -> 8
A11: Total | B11: =SUM(B4:B10) -> 172 | C11: =SUM(C4:C10) -> 27 | D11: =SUM(D4:D10) -> 0 | E11: =SUM(E4:E10) -> 199

Sheet Pivot_Resource
A1: Average Resource Utilization (Usage Hours) by Department | F1: =AVERAGE(Cleaned_Resource!$D$2:$D$201) -> 3.85
A3: Department | B3: Avg Usage Hours | C3: Resource Count | D3: Utilization Status
A4: Cardiology | B4: =IFERROR(AVERAGEIFS(Cleaned_Resource!$D$2:$D$201,Cleaned_Resource!$B$2:$B$201,"Cardiology"),0) -> 4.1818182 | C4: =COUNTIF(Cleaned_Resource!$B$2:$B$201,"Cardiology") -> 22 | D4: =IF(B4="","N/A",IF(B4>$F$1*1.1,"Overburdened",IF(B4<$F$1*0.9,"Underutilized","Normal"))) -> Normal
A5: General Medicine | B5: =IFERROR(AVERAGEIFS(Cleaned_Resource!$D$2:$D$201,Cleaned_Resource!$B$2:$B$201,"General Medicine"),0) -> 3.4102564 | C5: =COUNTIF(Cleaned_Resource!$B$2:$B$201,"General Medicine") -> 39 | D5: =IF(B5="","N/A",IF(B5>$F$1*1.1,"Overburdened",IF(B5<$F$1*0.9,"Underutilized","Normal"))) -> Underutilized
A6: Neurology | B6: =IFERROR(AVERAGEIFS(Cleaned_Resource!$D$2:$D$201,Cleaned_Resource!$B$2:$B$201,"Neurology"),0) -> 3.7941176 | C6: =COUNTIF(Cleaned_Resource!$B$2:$B$201,"Neurology") -> 34 | D6: =IF(B6="","N/A",IF(B6>$F$1*1.1,"Overburdened",IF(B6<$F$1*0.9,"Underutilized","Normal"))) -> Normal
A7: Oncology | B7: =IFERROR(AVERAGEIFS(Cleaned_Resource!$D$2:$D$201,Cleaned_Resource!$B$2:$B$201,"Oncology"),0) -> 3.5555556 | C7: =COUNTIF(Cleaned_Resource!$B$2:$B$201,"Oncology") -> 36 | D7: =IF(B7="","N/A",IF(B7>$F$1*1.1,"Overburdened",IF(B7<$F$1*0.9,"Underutilized","Normal"))) -> Normal
A8: Orthopedics | B8: =IFERROR(AVERAGEIFS(Cleaned_Resource!$D$2:$D$201,Cleaned_Resource!$B$2:$B$201,"Orthopedics"),0) -> 3.3703704 | C8: =COUNTIF(Cleaned_Resource!$B$2:$B$201,"Orthopedics") -> 27 | D8: =IF(B8="","N/A",IF(B8>$F$1*1.1,"Overburdened",IF(B8<$F$1*0.9,"Underutilized","Normal"))) -> Underutilized
A9: Pediatric | B9: =IFERROR(AVERAGEIFS(Cleaned_Resource!$D$2:$D$201,Cleaned_Resource!$B$2:$B$201,"Pediatric"),0) -> 4.85 | C9: =COUNTIF(Cleaned_Resource!$B$2:$B$201,"Pediatric") -> 40 | D9: =IF(B9="","N/A",IF(B9>$F$1*1.1,"Overburdened",IF(B9<$F$1*0.9,"Underutilized","Normal"))) -> Overburdened
A10: N/A | B10: =IFERROR(AVERAGEIFS(Cleaned_Resource!$D$2:$D$201,Cleaned_Resource!$B$2:$B$201,"N/A"),0) -> 1.5 | C10: =COUNTIF(Cleaned_Resource!$B$2:$B$201,"N/A") -> 2 | D10: =IF(B10="","N/A",IF(B10>$F$1*1.1,"Overburdened",IF(B10<$F$1*0.9,"Underutilized","Normal"))) -> Underutilized

Sheet Trends_Analysis
A1: Task 3: Trend Identification
A3: 1. Appointments by Day of Week | D3: 2. Appointments by Hour of Day
A5: Day | B5: Appointment Count | D5: Hour | E5: Appointment Count
A6: Monday | B6: =COUNTIF(Cleaned_Appointment!$I$2:$I$202,"Monday") -> 34 | D6: 8:00 | E6: =COUNTIF(Cleaned_Appointment!$H$2:$H$202,8) -> 18
A7: Tuesday | B7: =COUNTIF(Cleaned_Appointment!$I$2:$I$202,"Tuesday") -> 27 | D7: 9:00 | E7: =COUNTIF(Cleaned_Appointment!$H$2:$H$202,9) -> 15
A8: Wednesday | B8: =COUNTIF(Cleaned_Appointment!$I$2:$I$202,"Wednesday") -> 27 | D8: 10:00 | E8: =COUNTIF(Cleaned_Appointment!$H$2:$H$202,10) -> 14
A9: Thursday | B9: =COUNTIF(Cleaned_Appointment!$I$2:$I$202,"Thursday") -> 23 | D9: 11:00 | E9: =COUNTIF(Cleaned_Appointment!$H$2:$H$202,11) -> 17
A10: Friday | B10: =COUNTIF(Cleaned_Appointment!$I$2:$I$202,"Friday") -> 26 | D10: 12:00 | E10: =COUNTIF(Cleaned_Appointment!$H$2:$H$202,12) -> 18
A11: Saturday | B11: =COUNTIF(Cleaned_Appointment!$I$2:$I$202,"Saturday") -> 31 | D11: 13:00 | E11: =COUNTIF(Cleaned_Appointment!$H$2:$H$202,13) -> 12
A12: Sunday | B12: =COUNTIF(Cleaned_Appointment!$I$2:$I$202,"Sunday") -> 30 | D12: 14:00 | E12: =COUNTIF(Cleaned_Appointment!$H$2:$H$202,14) -> 13
A13: N/A | B13: =COUNTIF(Cleaned_Appointment!$I$2:$I$202,"N/A") -> 3 | D13: 15:00 | E13: =COUNTIF(Cleaned_Appointment!$H$2:$H$202,15) -> 19
D14: 16:00 | E14: =COUNTIF(Cleaned_Appointment!$H$2:$H$202,16) -> 18
A15: Busiest Day: | B15: =INDEX(A6:A13,MATCH(MAX(B6:B13),B6:B13,0)) -> Monday | D15: 17:00 | E15: =COUNTIF(Cleaned_Appointment!$H$2:$H$202,17) -> 20
D16: 18:00 | E16: =COUNTIF(Cleaned_Appointment!$H$2:$H$202,18) -> 27
D17: N/A | E17: =COUNTIF(Cleaned_Appointment!$H$2:$H$202,"N/A") -> 10
D19: Busiest Hour: | E19: =INDEX(D6:D17,MATCH(MAX(E6:E17),E6:E17,0)) -> 18:00
A20: 3. Average Feedback Score by Department (Highest / Lowest Satisfaction) | D20: 4. Low-Satisfaction Feedback Count by Appointment Hour
A22: Department | B22: Avg Feedback Score | D22: Hour | E22: Total Feedback | F22: Low Count | G22: Low %
A23: Cardiology | B23: =IFERROR(AVERAGEIFS(Combined_Dataset!$E$2:$E$200,Combined_Dataset!$D$2:$D$200,"Cardiology"),"N/A") -> 7.030303 | D23: 8:00 | E23: =COUNTIF(Combined_Dataset!$I$2:$I$200,8) -> 18 | F23: =COUNTIFS(Combined_Dataset!$I$2:$I$200,8,Combined_Dataset!$H$2:$H$200,"Low") -> 3 | G23: =IFERROR(F23/E23,0) -> 0.16666667
A24: General Medicine | B24: =IFERROR(AVERAGEIFS(Combined_Dataset!$E$2:$E$200,Combined_Dataset!$D$2:$D$200,"General Medicine"),"N/A") -> 5.3846154 | D24: 9:00 | E24: =COUNTIF(Combined_Dataset!$I$2:$I$200,9) -> 19 | F24: =COUNTIFS(Combined_Dataset!$I$2:$I$200,9,Combined_Dataset!$H$2:$H$200,"Low") -> 1 | G24: =IFERROR(F24/E24,0) -> 0.052631579
A25: Neurology | B25: =IFERROR(AVERAGEIFS(Combined_Dataset!$E$2:$E$200,Combined_Dataset!$D$2:$D$200,"Neurology"),"N/A") -> 6.2647059 | D25: 10:00 | E25: =COUNTIF(Combined_Dataset!$I$2:$I$200,10) -> 14 | F25: =COUNTIFS(Combined_Dataset!$I$2:$I$200,10,Combined_Dataset!$H$2:$H$200,"Low") -> 1 | G25: =IFERROR(F25/E25,0) -> 0.071428571
A26: Oncology | B26: =IFERROR(AVERAGEIFS(Combined_Dataset!$E$2:$E$200,Combined_Dataset!$D$2:$D$200,"Oncology"),"N/A") -> 6.5 | D26: 11:00 | E26: =COUNTIF(Combined_Dataset!$I$2:$I$200,11) -> 16 | F26: =COUNTIFS(Combined_Dataset!$I$2:$I$200,11,Combined_Dataset!$H$2:$H$200,"Low") -> 3 | G26: =IFERROR(F26/E26,0) -> 0.1875
A27: Orthopedics | B27: =IFERROR(AVERAGEIFS(Combined_Dataset!$E$2:$E$200,Combined_Dataset!$D$2:$D$200,"Orthopedics"),"N/A") -> 5.9310345 | D27: 12:00 | E27: =COUNTIF(Combined_Dataset!$I$2:$I$200,12) -> 19 | F27: =COUNTIFS(Combined_Dataset!$I$2:$I$200,12,Combined_Dataset!$H$2:$H$200,"Low") -> 1 | G27: =IFERROR(F27/E27,0) -> 0.052631579
A28: Pediatric | B28: =IFERROR(AVERAGEIFS(Combined_Dataset!$E$2:$E$200,Combined_Dataset!$D$2:$D$200,"Pediatric"),"N/A") -> 6.3243243 | D28: 13:00 | E28: =COUNTIF(Combined_Dataset!$I$2:$I$200,13) -> 9 | F28: =COUNTIFS(Combined_Dataset!$I$2:$I$200,13,Combined_Dataset!$H$2:$H$200,"Low") -> 1 | G28: =IFERROR(F28/E28,0) -> 0.11111111
A29: N/A | B29: =IFERROR(AVERAGEIFS(Combined_Dataset!$E$2:$E$200,Combined_Dataset!$D$2:$D$200,"N/A"),"N/A") -> 6.11125 | D29: 14:00 | E29: =COUNTIF(Combined_Dataset!$I$2:$I$200,14) -> 15 | F29: =COUNTIFS(Combined_Dataset!$I$2:$I$200,14,Combined_Dataset!$H$2:$H$200,"Low") -> 2 | G29: =IFERROR(F29/E29,0) -> 0.13333333
D30: 15:00 | E30: =COUNTIF(Combined_Dataset!$I$2:$I$200,15) -> 20 | F30: =COUNTIFS(Combined_Dataset!$I$2:$I$200,15,Combined_Dataset!$H$2:$H$200,"Low") -> 2 | G30: =IFERROR(F30/E30,0) -> 0.1
A31: Highest Satisfaction Dept: | B31: =INDEX(A23:A29,MATCH(MAX(B23:B29),B23:B29,0)) -> Cardiology | D31: 16:00 | E31: =COUNTIF(Combined_Dataset!$I$2:$I$200,16) -> 19 | F31: =COUNTIFS(Combined_Dataset!$I$2:$I$200,16,Combined_Dataset!$H$2:$H$200,"Low") -> 4 | G31: =IFERROR(F31/E31,0) -> 0.21052632
A32: Lowest Satisfaction Dept: | B32: =INDEX(A23:A29,MATCH(MIN(B23:B29),B23:B29,0)) -> General Medicine | D32: 17:00 | E32: =COUNTIF(Combined_Dataset!$I$2:$I$200,17) -> 21 | F32: =COUNTIFS(Combined_Dataset!$I$2:$I$200,17,Combined_Dataset!$H$2:$H$200,"Low") -> 2 | G32: =IFERROR(F32/E32,0) -> 0.095238095
D33: 18:00 | E33: =COUNTIF(Combined_Dataset!$I$2:$I$200,18) -> 28 | F33: =COUNTIFS(Combined_Dataset!$I$2:$I$200,18,Combined_Dataset!$H$2:$H$200,"Low") -> 7 | G33: =IFERROR(F33/E33,0) -> 0.25
D34: N/A | E34: =COUNTIF(Combined_Dataset!$I$2:$I$200,"N/A") -> 1 | F34: =COUNTIFS(Combined_Dataset!$I$2:$I$200,"N/A",Combined_Dataset!$H$2:$H$200,"Low") -> 0 | G34: =IFERROR(F34/E34,0) -> 0
D36: Hour with Highest Low% : | E36: =INDEX(D23:D34,MATCH(MAX(G23:G34),G23:G34,0)) -> 18:00
